Workbook

Sheet Problem Statement
A1: COURIER BILLING RECONCILIATION — DATA ANALYST PROJECT
A3: Business Scenario
A4: Company X is a large Indian e-commerce company that ships thousands of orders daily through multiple courier partners. Courier charges depend on (1) shipment weight and (2) delivery zone (distance between warehouse and customer). X wants to verify whether courier partners are charging the correct amount per order.
A6: Objective
A7: For every order, independently calculate the expected courier charge using X's own records, then compare it against the amount actually billed by the courier company — and flag orders that were overcharged or undercharged.
A9: Input Data (provided as separate sheets in this workbook)
A10: • Order Report — Order ID, SKU, and quantity for every line item in every order
A11: • SKU Master — gross weight (grams) of each product SKU
A12: • Pincode Zones — warehouse-to-customer pincode combinations mapped to a delivery zone (a–e)
A13: • Courier Invoice — courier's own AWB number, order ID, charged weight, zone, shipment type, and billed amount
A14: • Courier Rates — courier's rate card (fixed + additional charge per 0.5 kg slab, by zone and shipment type)
A16: Method
... A26: All calculations in the 'Order Level Calculation' and 'Summary' tabs are live formulas (SUMIF, INDEX/MATCH, CEILING) referencing the raw data tabs — nothing is hardcoded.

Sheet Summary
A1: COURIER BILLING RECONCILIATION — SUMMARY
B3: Count | C3: Amount (Rs.)
A4: Total orders where X has been correctly charged | B4: =COUNTIF('Order Level Calculation'!$K$2:$K$125,0) -> 22 | C4: =SUMIF('Order Level Calculation'!$K$2:$K$125,0,'Order Level Calculation'!$J$2:$J$125) -> 1826.9
A5: Total orders where X has been overcharged | B5: =COUNTIF('Order Level Calculation'!$K$2:$K$125,">0") -> 79 | C5: =SUMIF('Order Level Calculation'!$K$2:$K$125,">0",'Order Level Calculation'!$K$2:$K$125) -> 4426.6
A6: Total orders where X has been undercharged | B6: =COUNTIF('Order Level Calculation'!$K$2:$K$125,"<0") -> 23 | C6: =ABS(SUMIF('Order Level Calculation'!$K$2:$K$125,"<0",'Order Level Calculation'!$K$2:$K$125)) -> 575.1
A8: Note: Difference = Charges Billed by Courier − Expected Charge as per X. Positive = overcharged, negative = undercharged, zero = correctly charged.

Sheet Order Level Calculation
A1: Order ID | B1: AWB Number | C1: Total Weight as per X (KG) | D1: Weight Slab as per X (KG) | E1: Total Weight as per Courier Company (KG) | F1: Weight Slab charged by Courier Company (KG) | G1: Delivery Zone as per X | H1: Delivery Zone charged by Courier Company | I1: Expected Charge as per X (Rs.) | J1: Charges Billed by Courier Company (Rs.) | K1: Difference (Billed - Expected) (Rs.)
A2: ='Courier Invoice'!B2 -> 2001806232 | B2: ='Courier Invoice'!A2 -> 1091117222124 | C2: =SUMIF('Order Report'!$A:$A,$A2,'Order Report'!$D:$D)/1000 -> 1.302 | D2: =CEILING(C2,0.5) -> 1.5 | E2: =VALUE('Courier Invoice'!C2) -> 1.3 | F2: =CEILING(E2,0.5) -> 1.5 | G2: =INDEX('Pincode Zones'!$C:$C,MATCH('Courier Invoice'!D2&"-"&'Courier Invoice'!E2,'Pincode Zones'!$D:$D,0)) -> d | H2: ='Courier Invoice'!F2 -> d | I2: =(INDEX('Courier Rates'!$1:$2,2,MATCH("fwd_"&$G2&"_fixed",'Courier Rates'!$1:$1,0))+INDEX('Courier Rates'!$1:$2,2,MATCH("fwd_"&$G2&"_additional",'Courier Rates'!$1:$1,0))*MAX(0,(D2-0.5)/0.5))+IF(ISNUMBER(SEARCH("rto",'Courier Invoice'!G2)),(INDEX('Courier Rates'!$1:$2,2,MATCH("rto_"&$G2&"_fixed",'Courier Rates'!$1:$1,0))+INDEX('Courier Rates'!$1:$2,2,MATCH("rto_"&$G2&"_additional",'Courier Rates'!$1:$1,0))*MAX(0,(D2-0.5)/0.5)),0) -> 135 | J2: =VALUE('Courier Invoice'!H2) -> 135 | K2: =ROUND(J2-I2,2) -> 0
A3: ='Courier Invoice'!B3 -> 2001806273 | B3: ='Courier Invoice'!A3 -> 1091117222194 | C3: =SUMIF('Order Report'!$A:$A,$A3,'Order Report'!$D:$D)/1000 -> 0.615 | D3: =CEILING(C3,0.5) -> 1 | E3: =VALUE('Courier Invoice'!C3) -> 1 | F3: =CEILING(E3,0.5) -> 1 | G3: =INDEX('Pincode Zones'!$C:$C,MATCH('Courier Invoice'!D3&"-"&'Courier Invoice'!E3,'Pincode Zones'!$D:$D,0)) -> d | H3: ='Courier Invoice'!F3 -> d | I3: =(INDEX('Courier Rates'!$1:$2,2,MATCH("fwd_"&$G3&"_fixed",'Courier Rates'!$1:$1,0))+INDEX('Courier Rates'!$1:$2,2,MATCH("fwd_"&$G3&"_additional",'Courier Rates'!$1:$1,0))*MAX(0,(D3-0.5)/0.5))+IF(ISNUMBER(SEARCH("rto",'Courier Invoice'!G3)),(INDEX('Courier Rates'!$1:$2,2,MATCH("rto_"&$G3&"_fixed",'Courier Rates'!$1:$1,0))+INDEX('Courier Rates'!$1:$2,2,MATCH("rto_"&$G3&"_additional",'Courier Rates'!$1:$1,0))*MAX(0,(D3-0.5)/0.5)),0) -> 90.2 | J3: =VALUE('Courier Invoice'!H3) -> 90.2 | K3: =ROUND(J3-I3,2) -> 0
A4: ='Courier Invoice'!B4 -> 2001806408 | B4: ='Courier Invoice'!A4 -> 1091117222931 | C4: =SUMIF('Order Report'!$A:$A,$A4,'Order Report'!$D:$D)/1000 -> 2.265 | D4: =CEILING(C4,0.5) -> 2.5 | E4: =VALUE('Courier Invoice'!C4) -> 2.5 | F4: =CEILING(E4,0.5) -> 2.5 | G4: =INDEX('Pincode Zones'!$C:$C,MATCH('Courier Invoice'!D4&"-"&'Courier Invoice'!E4,'Pincode Zones'!$D:$D,0)) -> d | H4: ='Courier Invoice'!F4 -> d | I4: =(INDEX('Courier Rates'!$1:$2,2,MATCH("fwd_"&$G4&"_fixed",'Courier Rates'!$1:$1,0))+INDEX('Courier Rates'!$1:$2,2,MATCH("fwd_"&$G4&"_additional",'Courier Rates'!$1:$1,0))*MAX(0,(D4-0.5)/0.5))+IF(ISNUMBER(SEARCH("rto",'Courier Invoice'!G4)),(INDEX('Courier Rates'!$1:$2,2,MATCH("rto_"&$G4&"_fixed",'Courier Rates'!$1:$1,0))+INDEX('Courier Rates'!$1:$2,2,MATCH("rto_"&$G4&"_additional",'Courier Rates'!$1:$1,0))*MAX(0,(D4-0.5)/0.5)),0) -> 224.6 | J4: =VALUE('Courier Invoice'!H4) -> 224.6 | K4: =ROUND(J4-I4,2) -> 0
A5: ='Courier Invoice'!B5 -> 2001806458 | B5: ='Courier Invoice'!A5 -> 1091117223244 | C5: =SUMIF('Order Report'!$A:$A,$A5,'Order Report'!$D:$D)/1000 -> 0.7 | D5: =CEILING(C5,0.5) -> 1 | E5: =VALUE('Courier Invoice'!C5) -> 1 | F5: =CEILING(E5,0.5) -> 1 | G5: =INDEX('Pincode Zones'!$C:$C,MATCH('Courier Invoice'!D5&"-"&'Courier Invoice'!E5,'Pincode Zones'!$D:$D,0)) -> b | H5: ='Courier Invoice'!F5 -> b | I5: =(INDEX('Courier Rates'!$1:$2,2,MATCH("fwd_"&$G5&"_fixed",'Courier Rates'!$1:$1,0))+INDEX('Courier Rates'!$1:$2,2,MATCH("fwd_"&$G5&"_additional",'Courier Rates'!$1:$1,0))*MAX(0,(D5-0.5)/0.5))+IF(ISNUMBER(SEARCH("rto",'Courier Invoice'!G5)),(INDEX('Courier Rates'!$1:$2,2,MATCH("rto_"&$G5&"_fixed",'Courier Rates'!$1:$1,0))+INDEX('Courier Rates'!$1:$2,2,MATCH("rto_"&$G5&"_additional",'Courier Rates'!$1:$1,0))*MAX(0,(D5-0.5)/0.5)),0) -> 61.3 | J5: =VALUE('Courier Invoice'!H5) -> 61.3 | K5: =ROUND(J5-I5,2) -> 0
A6: ='Courier Invoice'!B6 -> 2001807012 | B6: ='Courier Invoice'!A6 -> 1091117229345 | C6: =SUMIF('Order Report'!$A:$A,$A6,'Order Report'!$D:$D)/1000 -> 0.24 | D6: =CEILING(C6,0.5) -> 0.5 | E6: =VALUE('Courier Invoice'!C6) -> 0.15 | F6: =CEILING(E6,0.5) -> 0.5 | G6: =INDEX('Pincode Zones'!$C:$C,MATCH('Courier Invoice'!D6&"-"&'Courier Invoice'!E6,'Pincode Zones'!$D:$D,0)) -> d | H6: ='Courier Invoice'!F6 -> d | I6: =(INDEX('Courier Rates'!$1:$2,2,MATCH("fwd_"&$G6&"_fixed",'Courier Rates'!$1:$1,0))+INDEX('Courier Rates'!$1:$2,2,MATCH("fwd_"&$G6&"_additional",'Courier Rates'!$1:$1,0))*MAX(0,(D6-0.5)/0.5))+IF(ISNUMBER(SEARCH("rto",'Courier Invoice'!G6)),(INDEX('Courier Rates'!$1:$2,2,MATCH("rto_"&$G6&"_fixed",'Courier Rates'!$1:$1,0))+INDEX('Courier Rates'!$1:$2,2,MATCH("rto_"&$G6&"_additional",'Courier Rates'!$1:$1,0))*MAX(0,(D6-0.5)/0.5)),0) -> 45.4 | J6: =VALUE('Courier Invoice'!H6) -> 45.4 | K6: =ROUND(J6-I6,2) -> 0
A7: ='Courier Invoice'!B7 -> 2001806686 | B7: ='Courier Invoice'!A7 -> 1091117229555 | C7: =SUMIF('Order Report'!$A:$A,$A7,'Order Report'!$D:$D)/1000 -> 0.24 | D7: =CEILING(C7,0.5) -> 0.5 | E7: =VALUE('Courier Invoice'!C7) -> 0.15 | F7: =CEILING(E7,0.5) -> 0.5 | G7: =INDEX('Pincode Zones'!$C:$C,MATCH('Courier Invoice'!D7&"-"&'Courier Invoice'!E7,'Pincode Zones'!$D:$D,0)) -> d | H7: ='Courier Invoice'!F7 -> d | I7: =(INDEX('Courier Rates'!$1:$2,2,MATCH("fwd_"&$G7&"_fixed",'Courier Rates'!$1:$1,0))+INDEX('Courier Rates'!$1:$2,2,MATCH("fwd_"&$G7&"_additional",'Courier Rates'!$1:$1,0))*MAX(0,(D7-0.5)/0.5))+IF(ISNUMBER(SEARCH("rto",'Courier Invoice'!G7)),(INDEX('Courier Rates'!$1:$2,2,MATCH("rto_"&$G7&"_fixed",'Courier Rates'!$1:$1,0))+INDEX('Courier Rates'!$1:$2,2,MATCH("rto_"&$G7&"_additional",'Courier Rates'!$1:$1,0))*MAX(0,(D7-0.5)/0.5)),0) -> 45.4 | J7: =VALUE('Courier Invoice'!H7) -> 45.4 | K7: =ROUND(J7-I7,2) -> 0
A8: ='Courier Invoice'!B8 -> 2001806885 | B8: ='Courier Invoice'!A8 -> 1091117229776 | C8: =SUMIF('Order Report'!$A:$A,$A8,'Order Report'!$D:$D)/1000 -> 0.84 | D8: =CEILING(C8,0.5) -> 1 | E8: =VALUE('Courier Invoice'!C8) -> 1 | F8: =CEILING(E8,0.5) -> 1 | G8: =INDEX('Pincode Zones'!$C:$C,MATCH('Courier Invoice'!D8&"-"&'Courier Invoice'!E8,'Pincode Zones'!$D:$D,0)) -> b | H8: ='Courier Invoice'!F8 -> b | I8: =(INDEX('Courier Rates'!$1:$2,2,MATCH("fwd_"&$G8&"_fixed",'Courier Rates'!$1:$1,0))+INDEX('Courier Rates'!$1:$2,2,MATCH("fwd_"&$G8&"_additional",'Courier Rates'!$1:$1,0))*MAX(0,(D8-0.5)/0.5))+IF(ISNUMBER(SEARCH("rto",'Courier Invoice'!G8)),(INDEX('Courier Rates'!$1:$2,2,MATCH("rto_"&$G8&"_fixed",'Courier Rates'!$1:$1,0))+INDEX('Courier Rates'!$1:$2,2,MATCH("rto_"&$G8&"_additional",'Courier Rates'!$1:$1,0))*MAX(0,(D8-0.5)/0.5)),0) -> 61.3 | J8: =VALUE('Courier Invoice'!H8) -> 61.3 | K8: =ROUND(J8-I8,2) -> 0
A9: ='Courier Invoice'!B9 -> 2001807058 | B9: ='Courier Invoice'!A9 -> 1091117323112 | C9: =SUMIF('Order Report'!$A:$A,$A9,'Order Report'!$D:$D)/1000 -> 1.168 | D9: =CEILING(C9,0.5) -> 1.5 | E9: =VALUE('Courier Invoice'!C9) -> 1.15 | F9: =CEILING(E9,0.5) -> 1.5 | G9: =INDEX('Pincode Zones'!$C:$C,MATCH('Courier Invoice'!D9&"-"&'Courier Invoice'!E9,'Pincode Zones'!$D:$D,0)) -> b | H9: ='Courier Invoice'!F9 -> b | I9: =(INDEX('Courier Rates'!$1:$2,2,MATCH("fwd_"&$G9&"_fixed",'Courier Rates'!$1:$1,0))+INDEX('Courier Rates'!$1:$2,2,MATCH("fwd_"&$G9&"_additional",'Courier Rates'!$1:$1,0))*MAX(0,(D9-0.5)/0.5))+IF(ISNUMBER(SEARCH("rto",'Courier Invoice'!G9)),(INDEX('Courier Rates'!$1:$2,2,MATCH("rto_"&$G9&"_fixed",'Courier Rates'!$1:$1,0))+INDEX('Courier Rates'!$1:$2,2,MATCH("rto_"&$G9&"_additional",'Courier Rates'!$1:$1,0))*MAX(0,(D9-0.5)/0.5)),0) -> 89.6 | J9: =VALUE('Courier Invoice'!H9) -> 89.6 | K9: =ROUND(J9-I9,2) -> 0
A10: ='Courier Invoice'!B10 -> 2001807186 | B10: ='Courier Invoice'!A10 -> 1091117323812 | C10: =SUMIF('Order Report'!$A:$A,$A10,'Order Report'!$D:$D)/1000 -> 0.5 | D10: =CEILING(C10,0.5) -> 0.5 | E10: =VALUE('Courier Invoice'!C10) -> 0.5 | F10: =CEILING(E10,0.5) -> 0.5 | G10: =INDEX('Pincode Zones'!$C:$C,MATCH('Courier Invoice'!D10&"-"&'Courier Invoice'!E10,'Pincode Zones'!$D:$D,0)) -> d | H10: ='Courier Invoice'!F10 -> d | I10: =(INDEX('Courier Rates'!$1:$2,2,MATCH("fwd_"&$G10&"_fixed",'Courier Rates'!$1:$1,0))+INDEX('Courier Rates'!$1:$2,2,MATCH("fwd_"&$G10&"_additional",'Courier Rates'!$1:$1,0))*MAX(0,(D10-0.5)/0.5))+IF(ISNUMBER(SEARCH("rto",'Courier Invoice'!G10)),(INDEX('Courier Rates'!$1:$2,2,MATCH("rto_"&$G10&"_fixed",'Courier Rates'!$1:$1,0))+INDEX('Courier Rates'!$1:$2,2,MATCH("rto_"&$G10&"_additional",'Courier Rates'!$1:$1,0))*MAX(0,(D10-0.5)/0.5)),0) -> 45.4 | J10: =VALUE('Courier Invoice'!H10) -> 45.4 | K10: =ROUND(J10-I10,2) -> 0
A11: ='Courier Invoice'!B11 -> 2001807290 | B11: ='Courier Invoice'!A11 -> 1091117324206 | C11: =SUMIF('Order Report'!$A:$A,$A11,'Order Report'!$D:$D)/1000 -> 0.5 | D11: =CEILING(C11,0.5) -> 0.5 | E11: =VALUE('Courier Invoice'!C11) -> 0.5 | F11: =CEILING(E11,0.5) -> 0.5 | G11: =INDEX('Pincode Zones'!$C:$C,MATCH('Courier Invoice'!D11&"-"&'Courier Invoice'!E11,'Pincode Zones'!$D:$D,0)) -> d | H11: ='Courier Invoice'!F11 -> d | I11: =(INDEX('Courier Rates'!$1:$2,2,MATCH("fwd_"&$G11&"_fixed",'Courier Rates'!$1:$1,0))+INDEX('Courier Rates'!$1:$2,2,MATCH("fwd_"&$G11&"_additional",'Courier Rates'!$1:$1,0))*MAX(0,(D11-0.5)/0.5))+IF(ISNUMBER(SEARCH("rto",'Courier Invoice'!G11)),(INDEX('Courier Rates'!$1:$2,2,MATCH("rto_"&$G11&"_fixed",'Courier Rates'!$1:$1,0))+INDEX('Courier Rates'!$1:$2,2,MATCH("rto_"&$G11&"_additional",'Courier Rates'!$1:$1,0))*MAX(0,(D11-0.5)/0.5)),0) -> 45.4 | J11: =VALUE('Courier Invoice'!H11) -> 45.4 | K11: =ROUND(J11-I11,2) -> 0
A12: ='Courier Invoice'!B12 -> 2001807814 | B12: ='Courier Invoice'!A12 -> 1091117326612 | C12: =SUMIF('Order Report'!$A:$A,$A12,'Order Report'!$D:$D)/1000 -> 0.607 | D12: =CEILING(C12,0.5) -> 1 | E12: =VALUE('Courier Invoice'!C12) -> 0.79 | F12: =CEILING(E12,0.5) -> 1 | G12: =INDEX('Pincode Zones'!$C:$C,MATCH('Courier Invoice'!D12&"-"&'Courier Invoice'!E12,'Pincode Zones'!$D:$D,0)) -> b | H12: ='Courier Invoice'!F12 -> b | I12: =(INDEX('Courier Rates'!$1:$2,2,MATCH("fwd_"&$G12&"_fixed",'Courier Rates'!$1:$1,0))+INDEX('Courier Rates'!$1:$2,2,MATCH("fwd_"&$G12&"_additional",'Courier Rates'!$1:$1,0))*MAX(0,(D12-0.5)/0.5))+IF(ISNUMBER(SEARCH("rto",'Courier Invoice'!G12)),(INDEX('Courier Rates'!$1:$2,2,MATCH("rto_"&$G12&"_fixed",'Courier Rates'!$1:$1,0))+INDEX('Courier Rates'!$1:$2,2,MATCH("rto_"&$G12&"_additional",'Courier Rates'!$1:$1,0))*MAX(0,(D12-0.5)/0.5)),0) -> 61.3 | J12: =VALUE('Courier Invoice'!H12) -> 61.3 | K12: =ROUND(J12-I12,2) -> 0
A13: ='Courier Invoice'!B13 -> 2001807931 | B13: ='Courier Invoice'!A13 -> 1091117327172 | C13: =SUMIF('Order Report'!$A:$A,$A13,'Order Report'!$D:$D)/1000 -> 0.607 | D13: =CEILING(C13,0.5) -> 1 | E13: =VALUE('Courier Invoice'!C13) -> 0.72 | F13: =CEILING(E13,0.5) -> 1 | G13: =INDEX('Pincode Zones'!$C:$C,MATCH('Courier Invoice'!D13&"-"&'Courier Invoice'!E13,'Pincode Zones'!$D:$D,0)) -> d | H13: ='Courier Invoice'!F13 -> d | I13: =(INDEX('Courier Rates'!$1:$2,2,MATCH("fwd_"&$G13&"_fixed",'Courier Rates'!$1:$1,0))+INDEX('Courier Rates'!$1:$2,2,MATCH("fwd_"&$G13&"_additional",'Courier Rates'!$1:$1,0))*MAX(0,(D13-0.5)/0.5))+IF(ISNUMBER(SEARCH("rto",'Courier Invoice'!G13)),(INDEX('Courier Rates'!$1:$2,2,MATCH("rto_"&$G13&"_fixed",'Courier Rates'!$1:$1,0))+INDEX('Courier Rates'!$1:$2,2,MATCH("rto_"&$G13&"_additional",'Courier Rates'!$1:$1,0))*MAX(0,(D13-0.5)/0.5)),0) -> 90.2 | J13: =VALUE('Courier Invoice'!H13) -> 90.2 | K13: =ROUND(J13-I13,2) -> 0
... A125: ='Courier Invoice'!B125 -> 2001811305 | B125: ='Courier Invoice'!A125 -> 1091121846136 | C125: =SUMIF('Order Report'!$A:$A,$A125,'Order Report'!$D:$D)/1000 -> 0.75 | D125: =CEILING(C125,0.5) -> 1 | E125: =VALUE('Courier Invoice'!C125) -> 0.5 | F125: =CEILING(E125,0.5) -> 0.5 | G125: =INDEX('Pincode Zones'!$C:$C,MATCH('Courier Invoice'!D125&"-"&'Courier Invoice'!E125,'Pincode Zones'!$D:$D,0)) -> b | H125: ='Courier Invoice'!F125 -> d | I125: =(INDEX('Courier Rates'!$1:$2,2,MATCH("fwd_"&$G125&"_fixed",'Courier Rates'!$1:$1,0))+INDEX('Courier Rates'!$1:$2,2,MATCH("fwd_"&$G125&"_additional",'Courier Rates'!$1:$1,0))*MAX(0,(D125-0.5)/0.5))+IF(ISNUMBER(SEARCH("rto",'Courier Invoice'!G125)),(INDEX('Courier Rates'!$1:$2,2,MATCH("rto_"&$G125&"_fixed",'Courier Rates'!$1:$1,0))+INDEX('Courier Rates'!$1:$2,2,MATCH("rto_"&$G125&"_additional",'Courier Rates'!$1:$1,0))*MAX(0,(D125-0.5)/0.5)),0) -> 61.3 | J125: =VALUE('Courier Invoice'!H125) -> 45.4 | K125: =ROUND(J125-I125,2) -> -15.9

Sheet Order Report
A1: ExternOrderNo | B1: SKU | C1: Order Qty | D1: Line Weight (g)
A2: 2001827036 | B2: 8904223818706 | C2: 1.00 | D2: =C2*IFERROR(INDEX('SKU Master'!$B:$B,MATCH(B2,'SKU Master'!$A:$A,0)),0) -> 127
A3: 2001827036 | B3: 8904223819093 | C3: 1.00 | D3: =C3*IFERROR(INDEX('SKU Master'!$B:$B,MATCH(B3,'SKU Master'!$A:$A,0)),0) -> 150
A4: 2001827036 | B4: 8904223819109 | C4: 1.00 | D4: =C4*IFERROR(INDEX('SKU Master'!$B:$B,MATCH(B4,'SKU Master'!$A:$A,0)),0) -> 100
A5: 2001827036 | B5: 8904223818430 | C5: 1.00 | D5: =C5*IFERROR(INDEX('SKU Master'!$B:$B,MATCH(B5,'SKU Master'!$A:$A,0)),0) -> 165
A6: 2001827036 | B6: 8904223819277 | C6: 1.00 | D6: =C6*IFERROR(INDEX('SKU Master'!$B:$B,MATCH(B6,'SKU Master'!$A:$A,0)),0) -> 350
A7: 2001827036 | B7: GIFTBOX202002 | C7: 1.00 | D7: =C7*IFERROR(INDEX('SKU Master'!$B:$B,MATCH(B7,'SKU Master'!$A:$A,0)),0) -> 500
A8: 2001827036 | B8: 8904223818638 | C8: 2.00 | D8: =C8*IFERROR(INDEX('SKU Master'!$B:$B,MATCH(B8,'SKU Master'!$A:$A,0)),0) -> 274
A9: 2001827036 | B9: SACHETS001 | C9: 1.00 | D9: =C9*IFERROR(INDEX('SKU Master'!$B:$B,MATCH(B9,'SKU Master'!$A:$A,0)),0) -> 10
A10: 2001825261 | B10: 8904223819024 | C10: 4.00 | D10: =C10*IFERROR(INDEX('SKU Master'!$B:$B,MATCH(B10,'SKU Master'!$A:$A,0)),0) -> 448
A11: 2001825261 | B11: 8904223819291 | C11: 4.00 | D11: =C11*IFERROR(INDEX('SKU Master'!$B:$B,MATCH(B11,'SKU Master'!$A:$A,0)),0) -> 448
A12: 2001825261 | B12: 8904223818638 | C12: 3.00 | D12: =C12*IFERROR(INDEX('SKU Master'!$B:$B,MATCH(B12,'SKU Master'!$A:$A,0)),0) -> 411
A13: 2001825261 | B13: 8904223818669 | C13: 1.00 | D13: =C13*IFERROR(INDEX('SKU Master'!$B:$B,MATCH(B13,'SKU Master'!$A:$A,0)),0) -> 240
A14: 2001825261 | B14: SACHETS001 | C14: 1.00 | D14: =C14*IFERROR(INDEX('SKU Master'!$B:$B,MATCH(B14,'SKU Master'!$A:$A,0)),0) -> 10
A15: 2001823564 | B15: 8904223819291 | C15: 2.00 | D15: =C15*IFERROR(INDEX('SKU Master'!$B:$B,MATCH(B15,'SKU Master'!$A:$A,0)),0) -> 224
A16: 2001823564 | B16: 8904223819031 | C16: 2.00 | D16: =C16*IFERROR(INDEX('SKU Master'!$B:$B,MATCH(B16,'SKU Master'!$A:$A,0)),0) -> 224
A17: 2001823564 | B17: 8904223819024 | C17: 2.00 | D17: =C17*IFERROR(INDEX('SKU Master'!$B:$B,MATCH(B17,'SKU Master'!$A:$A,0)),0) -> 224
A18: 2001822466 | B18: 8904223819468 | C18: 2.00 | D18: =C18*IFERROR(INDEX('SKU Master'!$B:$B,MATCH(B18,'SKU Master'!$A:$A,0)),0) -> 480
A19: 2001822466 | B19: 8904223819291 | C19: 8.00 | D19: =C19*IFERROR(INDEX('SKU Master'!$B:$B,MATCH(B19,'SKU Master'!$A:$A,0)),0) -> 896
A20: 2001821995 | B20: 8904223819130 | C20: 1.00 | D20: =C20*IFERROR(INDEX('SKU Master'!$B:$B,MATCH(B20,'SKU Master'!$A:$A,0)),0) -> 350
A21: 2001821995 | B21: 8904223818706 | C21: 1.00 | D21: =C21*IFERROR(INDEX('SKU Master'!$B:$B,MATCH(B21,'SKU Master'!$A:$A,0)),0) -> 127
A22: 2001821766 | B22: 8904223818591 | C22: 2.00 | D22: =C22*IFERROR(INDEX('SKU Master'!$B:$B,MATCH(B22,'SKU Master'!$A:$A,0)),0) -> 240
A23: 2001821750 | B23: 8904223818850 | C23: 1.00 | D23: =C23*IFERROR(INDEX('SKU Master'!$B:$B,MATCH(B23,'SKU Master'!$A:$A,0)),0) -> 240
A24: 2001821750 | B24: 8904223818430 | C24: 1.00 | D24: =C24*IFERROR(INDEX('SKU Master'!$B:$B,MATCH(B24,'SKU Master'!$A:$A,0)),0) -> 165
A25: 2001821750 | B25: 8904223819130 | C25: 1.00 | D25: =C25*IFERROR(INDEX('SKU Master'!$B:$B,MATCH(B25,'SKU Master'!$A:$A,0)),0) -> 350
A26: 2001821742 | B26: 8904223819468 | C26: 1.00 | D26: =C26*IFERROR(INDEX('SKU Master'!$B:$B,MATCH(B26,'SKU Master'!$A:$A,0)),0) -> 240
... A47: 2001819252 | B47: 8904223818706 | C47: 1.00 | D47: =C47*IFERROR(INDEX('SKU Master'!$B:$B,MATCH(B47,'SKU Master'!$A:$A,0)),0) -> 127
A48: 2001819252 | B48: SACHETS001 | C48: 1.00 | D48: =C48*IFERROR(INDEX('SKU Master'!$B:$B,MATCH(B48,'SKU Master'!$A:$A,0)),0) -> 10
A49: 2001818390 | B49: 8904223819147 | C49: 1.00 | D49: =C49*IFERROR(INDEX('SKU Master'!$B:$B,MATCH(B49,'SKU Master'!$A:$A,0)),0) -> 240
A50: 2001818390 | B50: 8904223818935 | C50: 4.00 | D50: =C50*IFERROR(INDEX('SKU Master'!$B:$B,MATCH(B50,'SKU Master'!$A:$A,0)),0) -> 480
A51: 2001818390 | B51: 8904223818683 | C51: 1.00 | D51: =C51*IFERROR(INDEX('SKU Master'!$B:$B,MATCH(B51,'SKU Master'!$A:$A,0)),0) -> 121
A52: 2001817160 | B52: 8904223818478 | C52: 1.00 | D52: =C52*IFERROR(INDEX('SKU Master'!$B:$B,MATCH(B52,'SKU Master'!$A:$A,0)),0) -> 350
A53: 2001817160 | B53: 8904223819284 | C53: 1.00 | D53: =C53*IFERROR(INDEX('SKU Master'!$B:$B,MATCH(B53,'SKU Master'!$A:$A,0)),0) -> 350
A54: 2001817093 | B54: 8904223816214 | C54: 1.00 | D54: =C54*IFERROR(INDEX('SKU Master'!$B:$B,MATCH(B54,'SKU Master'!$A:$A,0)),0) -> 120
A55: 2001817093 | B55: 8904223818874 | C55: 1.00 | D55: =C55*IFERROR(INDEX('SKU Master'!$B:$B,MATCH(B55,'SKU Master'!$A:$A,0)),0) -> 100
A56: 2001817093 | B56: 8904223819512 | C56: 1.00 | D56: =C56*IFERROR(INDEX('SKU Master'!$B:$B,MATCH(B56,'SKU Master'!$A:$A,0)),0) -> 210
A57: 2001817093 | B57: 8904223818881 | C57: 1.00 | D57: =C57*IFERROR(INDEX('SKU Master'!$B:$B,MATCH(B57,'SKU Master'!$A:$A,0)),0) -> 140
A58: 2001817093 | B58: 8904223819291 | C58: 2.00 | D58: =C58*IFERROR(INDEX('SKU Master'!$B:$B,MATCH(B58,'SKU Master'!$A:$A,0)),0) -> 224
A59: 2001817093 | B59: 8904223819031 | C59: 2.00 | D59: =C59*IFERROR(INDEX('SKU Master'!$B:$B,MATCH(B59,'SKU Master'!$A:$A,0)),0) -> 224
A60: 2001817093 | B60: 8904223819024 | C60: 2.00 | D60: =C60*IFERROR(INDEX('SKU Master'!$B:$B,MATCH(B60,'SKU Master'!$A:$A,0)),0) -> 224
...

Sheet SKU Master
A1: SKU | B1: Weight (g)
A2: 8904223815682 | B2: 210
A3: 8904223815859 | B3: 165
A4: 8904223815866 | B4: 113
A5: 8904223815873 | B5: 65
A6: 8904223816214 | B6: 120
A7: 8904223816665 | B7: 102
A8: 8904223817273 | B8: 65
A9: 8904223817334 | B9: 170
A10: 8904223817501 | B10: 350
A11: 8904223818430 | B11: 165
A12: 8904223818478 | B12: 350
A13: 8904223818553 | B13: 115
... A51: 8904223819437 | B51: 552
A52: GIFTBOX202001 | B52: 500
A53: GIFTBOX202004 | B53: 500
A54: GIFTBOX202002 | B54: 500
A55: 8904223819369 | B55: 170
A56: GIFTBOX202003 | B56: 500
A57: 8904223819123 | B57: 250
A58: GIFTBOX202002 | B58: 500
A59: 8904223819468 | B59: 240
A60: 8904223819260 | B60: 130
A61: 8904223819321 | B61: 600
A62: 8904223819338 | B62: 600
A63: 8904223819505 | B63: 210
A64: 8904223819499 | B64: 210
A65: 8904223819512 | B65: 210
A66: 8904223819543 | B66: 300
A67: SACHETS001 | B67: 10

Sheet Pincode Zones
A1: Warehouse Pincode | B1: Customer Pincode | C1: Zone | D1: Match Key
A2: 121003 | B2: 507101 | C2: d | D2: =A2&"-"&B2 -> 121003-507101
A3: 121003 | B3: 486886 | C3: d | D3: =A3&"-"&B3 -> 121003-486886
A4: 121003 | B4: 532484 | C4: d | D4: =A4&"-"&B4 -> 121003-532484
A5: 121003 | B5: 143001 | C5: b | D5: =A5&"-"&B5 -> 121003-143001
A6: 121003 | B6: 515591 | C6: d | D6: =A6&"-"&B6 -> 121003-515591
A7: 121003 | B7: 326502 | C7: d | D7: =A7&"-"&B7 -> 121003-326502
A8: 121003 | B8: 208019 | C8: b | D8: =A8&"-"&B8 -> 121003-208019
A9: 121003 | B9: 140301 | C9: b | D9: =A9&"-"&B9 -> 121003-140301
A10: 121003 | B10: 396001 | C10: d | D10: =A10&"-"&B10 -> 121003-396001
A11: 121003 | B11: 711106 | C11: d | D11: =A11&"-"&B11 -> 121003-711106
A12: 121003 | B12: 284001 | C12: b | D12: =A12&"-"&B12 -> 121003-284001
A13: 121003 | B13: 441601 | C13: d | D13: =A13&"-"&B13 -> 121003-441601
... A125: 121003 | B125: 302020 | C125: b | D125: =A125&"-"&B125 -> 121003-302020

Sheet Courier Invoice
A1: AWB Code | B1: Order ID | C1: Charged Weight | D1: Warehouse Pincode | E1: Customer Pincode | F1: Zone | G1: Type of Shipment | H1: Billing Amount (Rs.)
A2: 1091117222124 | B2: 2001806232 | C2: 1.3 | D2: 121003 | E2: 507101 | F2: d | G2: Forward charges | H2: 135
A3: 1091117222194 | B3: 2001806273 | C3: 1 | D3: 121003 | E3: 486886 | F3: d | G3: Forward charges | H3: 90.2
A4: 1091117222931 | B4: 2001806408 | C4: 2.5 | D4: 121003 | E4: 532484 | F4: d | G4: Forward charges | H4: 224.6
A5: 1091117223244 | B5: 2001806458 | C5: 1 | D5: 121003 | E5: 143001 | F5: b | G5: Forward charges | H5: 61.3
A6: 1091117229345 | B6: 2001807012 | C6: 0.15 | D6: 121003 | E6: 515591 | F6: d | G6: Forward charges | H6: 45.4
A7: 1091117229555 | B7: 2001806686 | C7: 0.15 | D7: 121003 | E7: 326502 | F7: d | G7: Forward charges | H7: 45.4
A8: 1091117229776 | B8: 2001806885 | C8: 1 | D8: 121003 | E8: 208019 | F8: b | G8: Forward charges | H8: 61.3
A9: 1091117323112 | B9: 2001807058 | C9: 1.15 | D9: 121003 | E9: 140301 | F9: b | G9: Forward charges | H9: 89.6
A10: 1091117323812 | B10: 2001807186 | C10: 0.5 | D10: 121003 | E10: 396001 | F10: d | G10: Forward charges | H10: 45.4
A11: 1091117324206 | B11: 2001807290 | C11: 0.5 | D11: 121003 | E11: 711106 | F11: d | G11: Forward charges | H11: 45.4
A12: 1091117326612 | B12: 2001807814 | C12: 0.79 | D12: 121003 | E12: 284001 | F12: b | G12: Forward charges | H12: 61.3
A13: 1091117327172 | B13: 2001807931 | C13: 0.72 | D13: 121003 | E13: 441601 | F13: d | G13: Forward charges | H13: 90.2
... A125: 1091121846136 | B125: 2001811305 | C125: 0.5 | D125: 121003 | E125: 302020 | F125: d | G125: Forward charges | H125: 45.4

Sheet Courier Rates
A1: fwd_a_fixed | B1: fwd_a_additional | C1: fwd_b_fixed | D1: fwd_b_additional | E1: fwd_c_fixed | F1: fwd_c_additional | G1: fwd_d_fixed | H1: fwd_d_additional | I1: fwd_e_fixed | J1: fwd_e_additional | K1: rto_a_fixed | L1: rto_a_additional | M1: rto_b_fixed | N1: rto_b_additional | O1: rto_c_fixed | P1: rto_c_additional | Q1: rto_d_fixed | R1: rto_d_additional | S1: rto_e_fixed | T1: rto_e_additional
A2: 29.5 | B2: 23.6 | C2: 33 | D2: 28.3 | E2: 40.1 | F2: 38.9 | G2: 45.4 | H2: 44.8 | I2: 56.6 | J2: 55.5 | K2: 13.6 | L2: 23.6 | M2: 20.5 | N2: 28.3 | O2: 31.9 | P2: 38.9 | Q2: 41.3 | R2: 44.8 | S2: 50.7 | T2: 55.5
